<?xml version="1.0" ?>
<!-- =================================================================================== -->
<!-- |    This document was autogenerated by xacro from car_chassis_2diff.xacro        | -->
<!-- |    EDITING THIS FILE BY HAND IS NOT RECOMMENDED                                 | -->
<!-- =================================================================================== -->
<robot name="car_chassis_2diff">
  <material name="blue">
    <color rgba="0.5 0.5 1 0.8"/>
  </material>
  <material name="white">
    <color rgba="0.6 0.6 0.6 1"/>
  </material>
  <link name="base_footprint">
    <visual>
      <origin rpy="0.0 0.0 0.0" xyz="0.0 0.0 0.0"/>
      <geometry>
        <box size="0.001 0.001 0.001"/>
      </geometry>
    </visual>
  </link>
  <gazebo reference="base_footprint">
    <turnGravityOff>false</turnGravityOff>
  </gazebo>
  <joint name="base_footprint_joint" type="fixed">
    <origin rpy="0 0 0" xyz="0 0 0.05"/>
    <parent link="base_footprint"/>
    <child link="base_link"/>
  </joint>
  <link name="base_link">
    <visual>
      <origin rpy="0 0 0" xyz="0 0 0"/>
      <geometry>
        <cylinder length="0.08" radius="0.17"/>
      </geometry>
      <material name="yellow">
        <color rgba="0.9 0.9 0.1 0.5"/>
      </material>
    </visual>
  </link>
  <joint name="lf_wheel_joint" type="continuous">
    <origin rpy="0 0 0" xyz="0.0 0.025 0.0"/>
    <parent link="lf_motor"/>
    <child link="lf_wheel_link"/>
    <axis xyz="0 1 0"/>
  </joint>
  <link name="lf_wheel_link">
    <visual>
      <origin rpy="1.570796326795 0 0" xyz="0 0 0"/>
      <geometry>
        <cylinder length="0.015" radius="0.03"/>
      </geometry>
      <material name="white"/>
    </visual>
    <collision>
      <origin rpy="1.570796326795 0 0" xyz="0 0 0"/>
      <geometry>
        <cylinder length="0.015" radius="0.03"/>
      </geometry>
    </collision>
    <inertial>
      <mass value="0.05"/>
      <inertia ixx="1.2187499999999998e-05" ixy="0" ixz="0" iyy="1.2187499999999998e-05" iyz="0" izz="2.2499999999999998e-05"/>
    </inertial>
  </link>
  <gazebo reference="lf_wheel_link">
    <material>Gazebo/Orange</material>
  </gazebo>
  <transmission name="lf_wheel_trans">
    <type>transmission_interface/SimpleTransmission</type>
    <actuator name="lf_motor">
      <mechanicalReduction>1</mechanicalReduction>
    </actuator>
    <joint name="lf_wheel_joint">
      <hardwareInterface>VelocityJointInterface</hardwareInterface>
    </joint>
  </transmission>
  <joint name="base_lf_motor_joint" type="fixed">
    <origin rpy="0 0 0" xyz="-0.03 0.1 -0.02"/>
    <parent link="base_link"/>
    <child link="lf_motor"/>
  </joint>
  <link name="lf_motor">
    <visual>
      <origin rpy="1.570796326795 0 0" xyz="0 0 0"/>
      <geometry>
        <cylinder length="0.05" radius="0.01"/>
      </geometry>
      <material name="blue"/>
    </visual>
    <collision>
      <origin rpy="1.570796326795 0 0" xyz="0 0 0"/>
      <geometry>
        <cylinder length="0.05" radius="0.01"/>
      </geometry>
    </collision>
    <inertial>
      <mass value="0.1"/>
      <inertia ixx="2.3333333333333336e-05" ixy="0" ixz="0" iyy="2.3333333333333336e-05" iyz="0" izz="5e-06"/>
    </inertial>
  </link>
  <gazebo reference="lf_motor">
    <material>Gazebo/Red</material>
  </gazebo>
  <joint name="rt_wheel_joint" type="continuous">
    <origin rpy="0 0 0" xyz="0.0 -0.025 0.0"/>
    <parent link="rt_motor"/>
    <child link="rt_wheel_link"/>
    <axis xyz="0 1 0"/>
  </joint>
  <link name="rt_wheel_link">
    <visual>
      <origin rpy="-1.570796326795 0 0" xyz="0 0 0"/>
      <geometry>
        <cylinder length="0.015" radius="0.03"/>
      </geometry>
      <material name="white"/>
    </visual>
    <collision>
      <origin rpy="-1.570796326795 0 0" xyz="0 0 0"/>
      <geometry>
        <cylinder length="0.015" radius="0.03"/>
      </geometry>
    </collision>
    <inertial>
      <mass value="0.05"/>
      <inertia ixx="1.2187499999999998e-05" ixy="0" ixz="0" iyy="1.2187499999999998e-05" iyz="0" izz="2.2499999999999998e-05"/>
    </inertial>
  </link>
  <gazebo reference="rt_wheel_link">
    <material>Gazebo/Orange</material>
  </gazebo>
  <transmission name="rt_wheel_trans">
    <type>transmission_interface/SimpleTransmission</type>
    <actuator name="rt_motor">
      <mechanicalReduction>1</mechanicalReduction>
    </actuator>
    <joint name="rt_wheel_joint">
      <hardwareInterface>VelocityJointInterface</hardwareInterface>
    </joint>
  </transmission>
  <joint name="base_rt_motor_joint" type="fixed">
    <origin rpy="0 0 0" xyz="-0.03 -0.1 -0.02"/>
    <parent link="base_link"/>
    <child link="rt_motor"/>
  </joint>
  <link name="rt_motor">
    <visual>
      <origin rpy="-1.570796326795 0 0" xyz="0 0 0"/>
      <geometry>
        <cylinder length="0.05" radius="0.01"/>
      </geometry>
      <material name="blue"/>
    </visual>
    <collision>
      <origin rpy="-1.570796326795 0 0" xyz="0 0 0"/>
      <geometry>
        <cylinder length="0.05" radius="0.01"/>
      </geometry>
    </collision>
    <inertial>
      <mass value="0.1"/>
      <inertia ixx="2.3333333333333336e-05" ixy="0" ixz="0" iyy="2.3333333333333336e-05" iyz="0" izz="5e-06"/>
    </inertial>
  </link>
  <gazebo reference="rt_motor">
    <material>Gazebo/Red</material>
  </gazebo>
  <joint name="base_caster_joint" type="fixed">
    <origin rpy="0 0 0" xyz="0.1 0 -0.04"/>
    <parent link="base_link"/>
    <child link="caster_link"/>
  </joint>
  <link name="caster_link">
    <visual>
      <origin rpy="0 0 0" xyz="0 0 0"/>
      <geometry>
        <sphere radius="0.01"/>
      </geometry>
      <material name="blue">
        <color rgba="0.1 0.1 0.1 1"/>
      </material>
    </visual>
    <collision>
      <origin rpy="0 0 0" xyz="0 0 0"/>
      <geometry>
        <sphere radius="0.01"/>
      </geometry>
    </collision>
    <inertial>
      <mass value="0.05"/>
      <inertia ixx="2.0000000000000003e-06" ixy="0" ixz="0" iyy="2.0000000000000003e-06" iyz="0" izz="2.0000000000000003e-06"/>
    </inertial>
  </link>
  <gazebo>
    <plugin filename="libgazebo_ros_diff_drive.so" name="differential_drive_controller">
      <updateRate>100</updateRate>
      <leftJoint>lf_wheel_joint</leftJoint>
      <rightJoint>rt_wheel_joint</rightJoint>
      <wheelSeparation>0.25</wheelSeparation>
      <wheelDiameter>0.06</wheelDiameter>
      <wheelAcceleration>1.0</wheelAcceleration>
      <wheelTorque>5</wheelTorque>
      <commandTopic>cmd_vel</commandTopic>
      <odometryFrame>odom</odometryFrame>
      <robotBaseFrame>base_footprint</robotBaseFrame>
    </plugin>
  </gazebo>
</robot>

